[2025-01-21T19:46:28.913+0000] {local_task_job_runner.py:123} INFO - ::group::Pre task execution logs
[2025-01-21T19:46:29.104+0000] {taskinstance.py:2612} INFO - Dependencies all met for dep_context=non-requeueable deps ti=<TaskInstance: detect_data_drift_notify_retrain.detect_data_drift_task manual__2025-01-21T19:26:38.017295+00:00 [queued]>
[2025-01-21T19:46:29.297+0000] {taskinstance.py:2612} INFO - Dependencies all met for dep_context=requeueable deps ti=<TaskInstance: detect_data_drift_notify_retrain.detect_data_drift_task manual__2025-01-21T19:26:38.017295+00:00 [queued]>
[2025-01-21T19:46:29.298+0000] {taskinstance.py:2865} INFO - Starting attempt 2 of 2
[2025-01-21T19:46:29.606+0000] {taskinstance.py:2888} INFO - Executing <Task(BranchPythonOperator): detect_data_drift_task> on 2025-01-21 19:26:38.017295+00:00
[2025-01-21T19:46:29.640+0000] {warnings.py:112} WARNING - /home/***/.local/lib/python3.12/site-packages/***/task/task_runner/standard_task_runner.py:70: DeprecationWarning: This process (pid=378) is multi-threaded, use of fork() may lead to deadlocks in the child.
  pid = os.fork()

[2025-01-21T19:46:29.644+0000] {standard_task_runner.py:72} INFO - Started process 397 to run task
[2025-01-21T19:46:29.662+0000] {standard_task_runner.py:104} INFO - Running: ['***', 'tasks', 'run', 'detect_data_drift_notify_retrain', 'detect_data_drift_task', 'manual__2025-01-21T19:26:38.017295+00:00', '--job-id', '178', '--raw', '--subdir', 'DAGS_FOLDER/monitoring-dag.py', '--cfg-path', '/tmp/tmppuhcvfsj']
[2025-01-21T19:46:29.680+0000] {standard_task_runner.py:105} INFO - Job 178: Subtask detect_data_drift_task
[2025-01-21T19:46:29.955+0000] {task_command.py:467} INFO - Running <TaskInstance: detect_data_drift_notify_retrain.detect_data_drift_task manual__2025-01-21T19:26:38.017295+00:00 [running]> on host d3de575648b4
[2025-01-21T19:46:30.249+0000] {taskinstance.py:3131} INFO - Exporting env vars: AIRFLOW_CTX_DAG_OWNER='RL' AIRFLOW_CTX_DAG_ID='detect_data_drift_notify_retrain' AIRFLOW_CTX_TASK_ID='detect_data_drift_task' AIRFLOW_CTX_EXECUTION_DATE='2025-01-21T19:26:38.017295+00:00' AIRFLOW_CTX_TRY_NUMBER='2' AIRFLOW_CTX_DAG_RUN_ID='manual__2025-01-21T19:26:38.017295+00:00'
[2025-01-21T19:46:30.250+0000] {taskinstance.py:731} INFO - ::endgroup::
[2025-01-21T19:46:30.294+0000] {baseoperator.py:405} WARNING - BranchPythonOperator.execute cannot be called outside TaskInstance!
[2025-01-21T19:46:30.296+0000] {monitoring-dag.py:83} INFO - Loading files from S3...
[2025-01-21T19:46:30.297+0000] {monitoring-dag.py:58} INFO - Starting to load files from S3...
[2025-01-21T19:46:30.375+0000] {credentials.py:1147} INFO - Found credentials in environment variables.
[2025-01-21T19:46:33.379+0000] {monitoring-dag.py:62} INFO - Loading reference file: covertype-final-project-jedha/covertype/reference/covtype_80.csv
[2025-01-21T19:52:20.541+0000] {job.py:229} INFO - Heartbeat recovered after 45.61 seconds
[2025-01-22T19:16:24.902+0000] {local_task_job_runner.py:123} INFO - ::group::Pre task execution logs
[2025-01-22T19:16:24.961+0000] {taskinstance.py:2602} INFO - Dependencies not met for <TaskInstance: detect_data_drift_notify_retrain.detect_data_drift_task manual__2025-01-21T19:26:38.017295+00:00 [failed]>, dependency 'Task Instance State' FAILED: Task is in the 'failed' state.
[2025-01-22T19:16:24.966+0000] {local_task_job_runner.py:166} INFO - Task is not able to be run
