[2025-01-21T23:50:05.309+0000] {local_task_job_runner.py:123} INFO - ::group::Pre task execution logs
[2025-01-21T23:50:05.398+0000] {taskinstance.py:2612} INFO - Dependencies all met for dep_context=non-requeueable deps ti=<TaskInstance: detect_data_drift_notify_retrain.detect_file_task manual__2025-01-21T23:49:48.622951+00:00 [queued]>
[2025-01-21T23:50:05.461+0000] {taskinstance.py:2612} INFO - Dependencies all met for dep_context=requeueable deps ti=<TaskInstance: detect_data_drift_notify_retrain.detect_file_task manual__2025-01-21T23:49:48.622951+00:00 [queued]>
[2025-01-21T23:50:05.463+0000] {taskinstance.py:2865} INFO - Starting attempt 1 of 2
[2025-01-21T23:50:05.516+0000] {taskinstance.py:2888} INFO - Executing <Task(BranchPythonOperator): detect_file_task> on 2025-01-21 23:49:48.622951+00:00
[2025-01-21T23:50:05.536+0000] {warnings.py:112} WARNING - /home/***/.local/lib/python3.12/site-packages/***/task/task_runner/standard_task_runner.py:70: DeprecationWarning: This process (pid=197) is multi-threaded, use of fork() may lead to deadlocks in the child.
  pid = os.fork()

[2025-01-21T23:50:05.540+0000] {standard_task_runner.py:72} INFO - Started process 202 to run task
[2025-01-21T23:50:05.541+0000] {standard_task_runner.py:104} INFO - Running: ['***', 'tasks', 'run', 'detect_data_drift_notify_retrain', 'detect_file_task', 'manual__2025-01-21T23:49:48.622951+00:00', '--job-id', '229', '--raw', '--subdir', 'DAGS_FOLDER/monitoring-dag.py', '--cfg-path', '/tmp/tmpvsrnfrae']
[2025-01-21T23:50:05.599+0000] {standard_task_runner.py:105} INFO - Job 229: Subtask detect_file_task
[2025-01-21T23:50:05.753+0000] {task_command.py:467} INFO - Running <TaskInstance: detect_data_drift_notify_retrain.detect_file_task manual__2025-01-21T23:49:48.622951+00:00 [running]> on host d3de575648b4
[2025-01-21T23:50:06.223+0000] {taskinstance.py:3131} INFO - Exporting env vars: AIRFLOW_CTX_DAG_OWNER='RL' AIRFLOW_CTX_DAG_ID='detect_data_drift_notify_retrain' AIRFLOW_CTX_TASK_ID='detect_file_task' AIRFLOW_CTX_EXECUTION_DATE='2025-01-21T23:49:48.622951+00:00' AIRFLOW_CTX_TRY_NUMBER='1' AIRFLOW_CTX_DAG_RUN_ID='manual__2025-01-21T23:49:48.622951+00:00'
[2025-01-21T23:50:06.230+0000] {taskinstance.py:731} INFO - ::endgroup::
[2025-01-21T23:50:06.350+0000] {baseoperator.py:405} WARNING - BranchPythonOperator.execute cannot be called outside TaskInstance!
[2025-01-21T23:50:06.415+0000] {credentials.py:1147} INFO - Found credentials in environment variables.
[2025-01-21T23:50:08.913+0000] {monitoring-dag.py:46} INFO - Checking file in S3: covertype-final-project-jedha/covertype/new_data/covtype_20.csv
[2025-01-21T23:50:17.348+0000] {monitoring-dag.py:48} INFO - File found in S3
[2025-01-21T23:50:17.384+0000] {python.py:240} INFO - Done. Returned value was: detect_data_drift_task
[2025-01-21T23:50:17.400+0000] {branch.py:38} INFO - Branch into detect_data_drift_task
[2025-01-21T23:50:17.401+0000] {skipmixin.py:230} INFO - Following branch ('detect_data_drift_task',)
[2025-01-21T23:50:17.457+0000] {skipmixin.py:278} INFO - Skipping tasks [('no_file_found_task', -1)]
[2025-01-21T23:50:17.641+0000] {taskinstance.py:340} INFO - ::group::Post task execution logs
[2025-01-21T23:50:17.643+0000] {taskinstance.py:352} INFO - Marking task as SUCCESS. dag_id=detect_data_drift_notify_retrain, task_id=detect_file_task, run_id=manual__2025-01-21T23:49:48.622951+00:00, execution_date=20250121T234948, start_date=20250121T235005, end_date=20250121T235017
[2025-01-21T23:50:17.797+0000] {local_task_job_runner.py:266} INFO - Task exited with return code 0
[2025-01-21T23:50:18.019+0000] {taskinstance.py:3900} INFO - 1 downstream tasks scheduled from follow-on schedule check
[2025-01-21T23:50:18.029+0000] {local_task_job_runner.py:245} INFO - ::endgroup::
